Workbook

Sheet Aeropuerto
B3: Afiliación | C3: Marzo | D3: Abril | E3: Mayo | F3: Junio | G3: Julio | H3: Agosto | I3: Setiembre | J3: Octubre | K3: Noviembre
B4: RQ Apto Auto 2025 | C4: 254 | D4: 280 | E4: 320 | F4: 360 | G4: 400 | H4: 320 | I4: 360 | J4: 380 | K4: 420
B5: Real Apto Auto | D5: 245 | E5: 254 | F5: 251 | G5: 257 | H5: 275 | I5: 288 | J5: 282 | K5: 275 | L5: =+K5/K4 -> 0.6547619
B6: Nuevos | D6: 24 | E6: 22 | F6: 41 | G6: 28 | H6: 42 | I6: 50 | J6: 12 | K6: 17
B7: Rotación | D7: =+(D5+D6)-E5 -> 15 | E7: =+(E5+E6)-F5 -> 25 | F7: =+(F5+F6)-G5 -> 35 | G7: =+(G5+G6)-H5 -> 10 | H7: =+(H5+H6)-I5 -> 29 | I7: =+(I5+I6)-J5 -> 56 | J7: =+(J5+J6)-K5 -> 19
B8: Desactivados por mes | D8: 26 | E8: 19 | F8: 18 | G8: 7 | H8: 37 | I8: 44 | J8: 29
C14: Enero | D14: Febrero | E14: Marzo
B15: RQ Apto Auto 2026 | C15: =280+60 -> 340 | D15: =+C15+60 -> 400 | E15: =+D15+60 -> 460
B16: Nuevos (30)
B17: Rotación (30)

Sheet FEBRERO-26
B2: Afiliación | C2: Ope proy | E2: 02/02/2026 - Sem 5 | J2: 09/02/2026 - Sem 6 | O2: 16/02/2026 - Sem 7 | T2: 23/02/2026 - Sem 8
C3: Solicitud Nuevos | D3: Solicitud Reconectados | E3: Activas | F3: Bolsa | G3: nuevos | H3: Total | I3: congelas | J3: Activas | K3: Bolsa | L3: Nuevos | M3: Total | N3: congelas | O3: Activas | P3: Bolsa | Q3: Nuevos | R3: Total | S3: congelas | T3: Activas | U3: Bolsa | V3: Nuevos | W3: Total | X3: congelas | Y3: Total cumplimiento | Z3: % de cumplimiento
B4: Aeropuerto Auto | C4: 60 | E4: 252 | F4: 6 | H4: =+I4+E4 -> 269 | I4: 17 | R4: =+O4+S4 -> 0 | W4: =+X4+T4 -> 0 | Y4: =+G4+L4+Q4+V4 -> 0 | Z4: =+Y4/(C4+D4) -> 0
B5: Aeropuerto Van | E5: 19 | H5: =+E5+I5 -> 20 | I5: 1 | R5: =+O5+S5 -> 0 | W5: =+T5+X5 -> 0 | Y5: =+G5+L5+Q5+V5 -> 0 | Z5: =+Y5/(C5+D5) -> #DIV/0!
B6: Total Flota | E6: =SUM(E4:E5) -> 271 | H6: =+H4+H5 -> 289 | J6: =+J4+J5 -> 0 | M6: =+M4+M5 -> 0 | N6: =+N4+N5 -> 0 | O6: =+O4+O5 -> 0 | R6: =+R4+R5 -> 0 | S6: =+S4+S5 -> 0 | T6: =+T4+T5 -> 0 | W6: =+W4+W5 -> 0 | X6: =+X4+X5 -> 0
C8: Solicitud Nuevos | D8: Solicitud Reconectados | E8: Activas | F8: Bolsa | G8: nuevos | H8: Total | I8: congelas | J8: Activas | K8: Bolsa | L8: Nuevos | M8: Total | N8: congelas | O8: Activas | P8: bolsa | Q8: nuevo | R8: Total | S8: congelas | T8: Activas | U8: Bolsa | V8: Nuevos | W8: Total | X8: congelas | Y8: Total cumplimiento | Z8: % de cumplimiento
B9: Aerolíneas Auto | C9: 30 | E9: 188 | F9: 22 | H9: =+E9+I9 -> 208 | I9: 20 | M9: =N9+J9 -> 0 | R9: =+S9+O9 -> 0 | W9: =+T9+X9 -> 0 | Y9: =+G9+L9+Q9+V9 -> 0 | Z9: =+Y9/(C9+D9) -> 0
C11: Solicitud Nuevos | D11: Solicitud Reconectados | E11: Activas | F11: Bolsa | G11: nuevos | H11: Total | I11: congelas | J11: Activas | K11: Bolsa | L11: Nuevos | M11: Total | N11: congelas | O11: Activas | P11: bolsa | Q11: nuevo | R11: Total | S11: congelas | T11: Activas | U11: Bolsa | V11: Nuevos | W11: Total | X11: congelas | Y11: Total cumplimiento | Z11: % de cumplimiento
B12: Ciudad | C12: 30 | E12: 258 | F12: 13 | G12: 7 | H12: =+E12+I12 -> 309 | I12: 51 | M12: =+J12+N12 -> 0 | R12: =+O12+S12 -> 0 | W12: =+T12+X12 -> 0 | Y12: =+G12+L12+Q12+V12 -> 7 | Z12: =+Y12/(C12+D12) -> 0.23333333
B14: Plazas | C14: Solicitud Nuevos | D14: Solicitud Reconectados | E14: Activas | F14: Bolsa | G14: nuevos | H14: Total | I14: congelas | J14: Activas | K14: Bolsa | L14: Nuevos | M14: Total | N14: congelas | O14: Activas | P14: bolsa | Q14: nuevo | R14: Total | S14: congelas | T14: Activas | U14: Bolsa | V14: Nuevos | W14: Total | X14: congelas | Y14: Total cumplimiento | Z14: % de cumplimiento
B15: Jockey | C15: 2 | E15: 83 | F15: 2 | G15: 1 | H15: =+E15+I15 -> 83 | I15: 0 | M15: =+J15+N15 -> 0 | R15: =+O15+S15 -> 0 | W15: =+T15+X15 -> 0 | Y15: =+G15+L15+Q15+V15 -> 1 | Z15: =+Y15/(C15+D15) -> 0.5
B16: Bellavista | C16: 2 | E16: 40 | H16: =+E16+I16 -> 40 | I16: 0 | M16: =+J16+N16 -> 0 | R16: =+O16+S16 -> 0 | W16: =+T16+X16 -> 0 | Y16: =+G16+L16+Q16+V16 -> 0 | Z16: =+Y16/(C16+D16) -> 0
B17: Total flota | E17: =SUM(E15:E16) -> 123 | H17: =SUM(H15:H16) -> 123 | I17: =SUM(I15:I16) -> 0 | J17: =SUM(J15:J16) -> 0 | M17: =SUM(M15:M16) -> 0 | N17: =SUM(N15:N16) -> 0 | R17: =R15+R16 -> 0 | T17: =+T15+T16 -> 0 | W17: =W15+W16 -> 0

Sheet ENERO-26
B2: Afiliación | C2: Ope proy | E2: 05/01/2026 - Sem 1 | J2: 12/01/2026 - Sem 2 | O2: 19/01/2026 - Sem 3 | T2: 26/01/2026 - Sem 4
C3: Solicitud Nuevos | D3: Solicitud Reconectados | E3: Activas | F3: Bolsa | G3: nuevos | H3: Total | I3: congelas | J3: Activas | K3: Bolsa | L3: Nuevos | M3: Total | N3: congelas | O3: Activas | P3: Bolsa | Q3: Nuevos | R3: Total | S3: congelas | T3: Activas | U3: Bolsa | V3: Nuevos | W3: Total | X3: congelas | Y3: Total cumplimiento | Z3: % de cumplimiento
B4: Aeropuerto Auto | C4: 60 | E4: 270 | F4: 11 | G4: 4 | H4: =+I4+E4 -> 285 | I4: 15 | J4: 265 | K4: 7 | L4: 3 | M4: =+N4+J4 -> 282 | N4: 17 | O4: 259 | P4: 5 | Q4: 3 | R4: =+O4+S4 -> 273 | S4: 14 | T4: 267 | U4: 11 | V4: 4 | W4: =+X4+T4 -> 281 | X4: 14 | Y4: =+G4+L4+Q4+V4 -> 14 | Z4: =+Y4/(C4+D4) -> 0.23333333
B5: Aeropuerto Van | E5: 18 | H5: =+E5+I5 -> 18 | I5: 0 | J5: 18 | M5: =+J5+N5 -> 18 | O5: 19 | R5: =+O5+S5 -> 20 | S5: 1 | T5: 19 | W5: =+T5+X5 -> 20 | X5: 1 | Y5: =+G5+L5+Q5+V5 -> 0 | Z5: =+Y5/(C5+D5) -> #DIV/0!
B6: Total Flota | H6: =+H4+H5 -> 303 | J6: =+J4+J5 -> 283 | M6: =+M4+M5 -> 300 | N6: =+N4+N5 -> 17 | O6: =+O4+O5 -> 278 | R6: =+R4+R5 -> 293 | S6: =+S4+S5 -> 15 | T6: =+T4+T5 -> 286 | W6: =+W4+W5 -> 301 | X6: =+X4+X5 -> 15
C8: Solicitud Nuevos | D8: Solicitud Reconectados | E8: Activas | F8: Bolsa | G8: nuevos | H8: Total | I8: congelas | J8: Activas | K8: Bolsa | L8: Nuevos | M8: Total | N8: congelas | O8: Activas | P8: bolsa | Q8: nuevo | R8: Total | S8: congelas | T8: Activas | U8: Bolsa | V8: Nuevos | W8: Total | X8: congelas | Y8: Total cumplimiento | Z8: % de cumplimiento
B9: Aerolíneas Auto | C9: 30 | E9: 169 | F9: 12 | G9: 2 | H9: =+E9+I9 -> 189 | I9: 20 | J9: 177 | K9: 14 | L9: 7 | M9: =N9+J9 -> 198 | N9: 21 | O9: 181 | P9: 16 | Q9: 5 | R9: =+S9+O9 -> 201 | S9: 20 | T9: 190 | U9: 16 | V9: 4 | W9: =+T9+X9 -> 226 | X9: 36 | Y9: =+G9+L9+Q9+V9 -> 18 | Z9: =+Y9/(C9+D9) -> 0.6
C11: Solicitud Nuevos | D11: Solicitud Reconectados | E11: Activas | F11: Bolsa | G11: nuevos | H11: Total | I11: congelas | J11: Activas | K11: Bolsa | L11: Nuevos | M11: Total | N11: congelas | O11: Activas | P11: bolsa | Q11: nuevo | R11: Total | S11: congelas | T11: Activas | U11: Bolsa | V11: Nuevos | W11: Total | X11: congelas | Y11: Total cumplimiento | Z11: % de cumplimiento
B12: Ciudad | C12: 30 | E12: 234 | F12: 17 | G12: 8 | H12: =+E12+I12 -> 294 | I12: 60 | J12: 257 | K12: 17 | L12: 5 | M12: =+J12+N12 -> 298 | N12: 41 | O12: 261 | P12: 13 | Q12: 5 | R12: =+O12+S12 -> 315 | S12: 54 | T12: 267 | U12: 13 | V12: 3 | W12: =+T12+X12 -> 315 | X12: 48 | Y12: =+G12+L12+Q12+V12 -> 21 | Z12: =+Y12/(C12+D12) -> 0.7
B14: Plazas | C14: Solicitud Nuevos | D14: Solicitud Reconectados | E14: Activas | F14: Bolsa | G14: nuevos | H14: Total | I14: congelas | J14: Activas | K14: Bolsa | L14: Nuevos | M14: Total | N14: congelas | O14: Activas | P14: bolsa | Q14: nuevo | R14: Total | S14: congelas | T14: Activas | U14: Bolsa | V14: Nuevos | W14: Total | X14: congelas | Y14: Total cumplimiento | Z14: % de cumplimiento
B15: Jockey | C15: 2 | E15: 77 | F15: 0 | G15: 0 | H15: =+E15+I15 -> 77 | I15: 0 | J15: 77 | K15: 0 | L15: 0 | M15: =+J15+N15 -> 77 | N15: 0 | O15: 78 | P15: 1 | Q15: 0 | R15: =+O15+S15 -> 78 | S15: 0 | T15: 82 | U15: 2 | V15: 1 | W15: =+T15+X15 -> 82 | X15: 0 | Y15: =+G15+L15+Q15+V15 -> 1 | Z15: =+Y15/(C15+D15) -> 0.5
B16: Bellavista | C16: 2 | E16: 36 | F16: 1 | G16: 1 | H16: =+E16+I16 -> 36 | I16: 0 | J16: 36 | K16: 0 | L16: 0 | M16: =+J16+N16 -> 36 | N16: 0 | O16: 40 | P16: 0 | Q16: 0 | R16: =+O16+S16 -> 40 | S16: 0 | T16: 38 | U16: 0 | W16: =+T16+X16 -> 38 | X16: 0 | Y16: =+G16+L16+Q16+V16 -> 1 | Z16: =+Y16/(C16+D16) -> 0.5
B17: Total flota | E17: =SUM(E15:E16) -> 113 | H17: =SUM(H15:H16) -> 113 | I17: =SUM(I15:I16) -> 0 | J17: =SUM(J15:J16) -> 113 | M17: =SUM(M15:M16) -> 113 | N17: =SUM(N15:N16) -> 0 | R17: =R15+R16 -> 118 | T17: =+T15+T16 -> 120 | W17: =W15+W16 -> 120

Sheet DICIEMBRE
B2: Afiliación | C2: Ope proy | E2: 01/12/2025 - Sem 48 | J2: 08/12/2025 - Sem 49 | O2: 15/12/2025 - Sem 50 | T2: 22/12/2025 - Sem 51 | Y2: 29/12/2025 - Sem 52
C3: Solicitud Nuevos | D3: Solicitud Reconectados | E3: Activas | F3: Bolsa | G3: nuevos | H3: Total | I3: congelas | J3: Activas | K3: Bolsa | L3: Nuevos | M3: Total | N3: congelas | O3: Activas | P3: Bolsa | Q3: Nuevos | R3: Total | S3: congelas | T3: Activas | U3: Bolsa | V3: Nuevos | W3: Total | X3: congelas | Y3: Activas | Z3: Bolsa | AA3: Nuevos | AB3: Total | AC3: congelas | AD3: Total cumplimiento | AE3: % de cumplimiento
B4: Aeropuerto Auto | C4: 50 | E4: 287 | F4: 10 | G4: 6 | H4: =+I4+E4 -> 300 | I4: 13 | J4: 284 | K4: 9 | L4: 3 | M4: =+N4+J4 -> 300 | N4: 16 | O4: 286 | P4: 12 | Q4: 9 | R4: =+S4+O4 -> 298 | S4: 12 | T4: 287 | U4: 9 | V4: 1 | W4: =+X4+T4 -> 297 | X4: 10 | Y4: 284 | Z4: 10 | AA4: 0 | AB4: =+AC4+Y4 -> 298 | AC4: 14 | AD4: =+G4+L4+Q4+V4+AA4 -> 19 | AE4: =+AD4/(C4+D4) -> 0.38
B5: Aeropuerto Van | E5: 11 | F5: 0 | G5: 0 | H5: =+E5+I5 -> 17 | I5: 6 | J5: 15 | K5: 0 | L5: 0 | M5: =+J5+N5 -> 16 | N5: 1 | O5: 16 | P5: 0 | Q5: 0 | R5: =+O5+S5 -> 16 | S5: 0 | T5: 17 | U5: 0 | V5: 0 | W5: =+T5+X5 -> 17 | X5: 0 | Y5: 17 | Z5: 0 | AA5: 0 | AB5: =+Y5+AC5 -> 18 | AC5: 1 | AD5: =+G5+L5+Q5+V5+AA5 -> 0 | AE5: =+AD5/(C5+D5) -> #DIV/0!
B6: Total Flota | F6: =SUM(F4:F5) -> 10 | G6: =SUM(G4:G5) -> 6 | H6: =+H4+H5 -> 317 | I6: =SUM(I4:I5) -> 19 | J6: =+J4+J5 -> 299 | K6: =SUM(K4:K5) -> 9 | L6: =SUM(L4:L5) -> 3 | M6: =+M4+M5 -> 316 | N6: =+N4+N5 -> 17 | O6: =+O4+O5 -> 302 | P6: =SUM(P4:P5) -> 12 | Q6: =SUM(Q4:Q5) -> 9 | R6: =+R4+R5 -> 314 | S6: =+S4+S5 -> 12 | T6: =+T4+T5 -> 304 | U6: =SUM(U4:U5) -> 9 | V6: =SUM(V4:V5) -> 1 | W6: =+W4+W5 -> 314 | X6: =+X4+X5 -> 10 | Y6: =+Y4+Y5 -> 301 | Z6: =SUM(Z4:Z5) -> 10 | AA6: =SUM(AA4:AA5) -> 0 | AB6: =+AB4+AB5 -> 316 | AC6: =+AC4+AC5 -> 15
C8: Solicitud Nuevos | D8: Solicitud Reconectados | E8: Activas | F8: Bolsa | G8: nuevos | H8: Total | I8: congelas | J8: Activas | K8: Bolsa | L8: Nuevos | M8: Total | N8: congelas | O8: Activas | P8: bolsa | Q8: nuevo | R8: Total | S8: congelas | T8: Activas | U8: Bolsa | V8: Nuevos | W8: Total | X8: congelas | Y8: Activas | Z8: Bolsa | AA8: Nuevos | AB8: Total | AC8: congelas | AD8: Total cumplimiento | AE8: % de cumplimiento
B9: Aerolíneas Auto | C9: 28 | E9: 183 | F9: 6 | G9: 0 | H9: =+E9+I9 -> 207 | I9: 24 | J9: 179 | K9: 9 | L9: 1 | M9: =N9+J9 -> 203 | N9: 24 | O9: 181 | P9: 11 | Q9: 2 | R9: =+O9+S9 -> 196 | S9: 15 | T9: 172 | U9: 14 | V9: 3 | W9: =+T9+X9 -> 187 | X9: 15 | Y9: 179 | Z9: 10 | AA9: 0 | AB9: =+Y9+AC9 -> 196 | AC9: 17 | AD9: =+G9+L9+Q9+V9+AA9 -> 6 | AE9: =+AD9/(C9+D9) -> 0.21428571
C11: Solicitud Nuevos | D11: Solicitud Reconectados | E11: Activas | F11: Bolsa | G11: nuevos | H11: Total | I11: congelas | J11: Activas | K11: Bolsa | L11: Nuevos | M11: Total | N11: congelas | O11: Activas | P11: bolsa | Q11: nuevo | R11: Total | S11: congelas | T11: Activas | U11: Bolsa | V11: Nuevos | W11: Total | X11: congelas | Y11: Activas | Z11: Bolsa | AA11: Nuevos | AB11: Total | AC11: congelas | AD11: Total cumplimiento | AE11: % de cumplimiento
B12: Ciudad | C12: 33 | E12: 289 | F12: 15 | G12: 4 | H12: =+E12+I12 -> 333 | I12: 44 | J12: 263 | K12: 14 | L12: 7 | M12: =+J12+N12 -> 323 | N12: 60 | O12: 268 | P12: 12 | Q12: 4 | R12: =+O12+S12 -> 321 | S12: 53 | T12: 266 | U12: 9 | V12: 0 | W12: =+T12+X12 -> 321 | X12: 55 | Y12: 251 | Z12: 17 | AA12: 0 | AB12: =+Y12+AC12 -> 307 | AC12: 56 | AD12: =+G12+L12+Q12+V12+AA12 -> 15 | AE12: =+AD12/(C12+D12) -> 0.45454545
B14: Plazas | C14: Solicitud Nuevos | D14: Solicitud Reconectados | E14: Activas | F14: Bolsa | G14: nuevos | H14: Total | I14: congelas | J14: Activas | K14: Bolsa | L14: Nuevos | M14: Total | N14: congelas | O14: Activas | P14: bolsa | Q14: nuevo | R14: Total | S14: congelas | T14: Activas | U14: Bolsa | V14: Nuevos | W14: Total | X14: congelas | Y14: Activas | Z14: Bolsa | AA14: Nuevos | AB14: Total | AC14: congelas | AD14: Total cumplimiento | AE14: % de cumplimiento
B15: Jockey | C15: 5 | E15: 81 | F15: 1 | G15: 1 | H15: =+E15+I15 -> 81 | J15: 81 | K15: 1 | L15: 1 | M15: =+J15+N15 -> 81 | N15: 0 | O15: 82 | P15: 2 | Q15: 0 | R15: =+O15+S15 -> 82 | S15: 0 | T15: 83 | U15: 2 | V15: 2 | W15: =+T15+X15 -> 83 | X15: 0 | Y15: 80 | Z15: 1 | AA15: 0 | AB15: =+Y15+AC15 -> 80 | AC15: 0 | AD15: =+G15+L15+Q15+V15+AA15 -> 4 | AE15: =+AD15/(C15+D15) -> 0.8
B16: Bellavista | C16: 2 | E16: 40 | F16: 0 | G16: 0 | H16: =+E16+I16 -> 40 | J16: 39 | K16: 0 | L16: 0 | M16: =+J16+N16 -> 39 | N16: 0 | O16: 39 | P16: 0 | Q16: 0 | R16: =+O16+S16 -> 39 | S16: 0 | T16: 38 | U16: 0 | V16: 0 | W16: =+T16+X16 -> 38 | X16: 0 | Y16: 38 | Z16: 1 | AA16: 0 | AB16: =+Y16+AC16 -> 38 | AC16: 0 | AD16: =+G16+L16+Q16+V16+AA16 -> 0 | AE16: =+AD16/(C16+D16) -> 0
B17: Total flota | E17: =SUM(E15:E16) -> 121 | F17: =SUM(F15:F16) -> 1 | G17: =SUM(G15:G16) -> 1 | H17: =SUM(H15:H16) -> 121 | I17: =SUM(I15:I16) -> 0 | J17: =SUM(J15:J16) -> 120 | K17: =SUM(K15:K16) -> 1 | L17: =SUM(L15:L16) -> 1 | ... N17: =SUM(N15:N16) -> 0 | O17: =+O15+O16 -> 121 | P17: =SUM(P15:P16) -> 2 | Q17: =SUM(Q15:Q16) -> 0 | R17: =R15+R16 -> 121 | T17: =+T15+T16 -> 121 | U17: =SUM(U15:U16) -> 2 | V17: =SUM(V15:V16) -> 2 | W17: =W15+W16 -> 121 | Y17: =+Y15+Y16 -> 118 | Z17: =SUM(Z15:Z16) -> 2 | AA17: =SUM(AA15:AA16) -> 0 | AB17: =AB15+AB16 -> 118

Sheet NOVIEMBRE
B2: Afiliación | C2: Ope proy | E2: 03/11/2025 - Sem 44 | J2: 10/11/2025 - Sem 45 | O2: 17/11/2025 - Sem 46 | T2: 24/11/2025 - Sem 47
C3: Solicitud Nuevos | D3: Solicitud Reconectados | E3: Activas | F3: Bolsa | G3: nuevos | H3: Total | I3: congelas | J3: Activas | K3: Bolsa | L3: Nuevos | M3: Total | N3: congelas | O3: Activas | P3: Bolsa | Q3: Nuevos | R3: Total | S3: congelas | T3: Activas | U3: Bolsa | V3: Nuevos | W3: Total | X3: congelas | Y3: Total cumplimiento | Z3: % de cumplimiento
B4: Aeropuerto Auto | C4: 56 | E4: 273 | F4: 8 | G4: 3 | H4: =+I4+E4 -> 297 | I4: 24 | J4: 266 | K4: 11 | L4: 4 | M4: =+N4+J4 -> 293 | N4: 27 | O4: 281 | P4: 12 | Q4: 5 | R4: =+S4+O4 -> 296 | S4: 15 | T4: 275 | U4: 11 | V4: 5 | W4: =+X4+T4 -> 289 | X4: 14 | Y4: =+G4+L4+Q4+V4 -> 17 | Z4: =+Y4/(C4+D4) -> 0.30357143
B5: Aeropuerto Van | C5: 8 | E5: 31 | H5: =+E5+I5 -> 48 | I5: 17 | J5: 33 | M5: =+J5+N5 -> 49 | N5: 16 | O5: 34 | R5: =+O5+S5 -> 52 | S5: 18 | T5: 33 | W5: =+T5+X5 -> 51 | X5: 18 | Y5: =+G5+L5+Q5+V5 -> 0 | Z5: =+Y5/(C5+D5) -> 0
B6: Total Flota | E6: =E4+E5 -> 304 | F6: =+F4+F5 -> 8 | G6: =G4+G5 -> 3 | H6: =+H4+H5 -> 345 | I6: =+I4+I5 -> 41 | J6: =+J4+J5 -> 299 | K6: =SUM(K4:K5) -> 11 | L6: =SUM(L4:L5) -> 4 | M6: =+M4+M5 -> 342 | N6: =+N4+N5 -> 43 | O6: =+O4+O5 -> 315 | P6: =SUM(P4:P5) -> 12 | Q6: =SUM(Q4:Q5) -> 5 | R6: =+R4+R5 -> 348 | S6: =+S4+S5 -> 33 | T6: =+T4+T5 -> 308 | U6: =SUM(U4:U5) -> 11 | V6: =+V4+V5 -> 5 | W6: =+W4+W5 -> 340 | X6: =+X4+X5 -> 32
C8: Solicitud Nuevos | D8: Solicitud Reconectados | E8: Activas | F8: Bolsa | G8: nuevos | H8: Total | I8: congelas | J8: Activas | K8: Bolsa | L8: Nuevos | M8: Total | N8: congelas | O8: Activas | P8: bolsa | Q8: nuevo | R8: Total | S8: congelas | T8: Activas | U8: Bolsa | V8: Nuevos | W8: Total | X8: congelas | Y8: Total cumplimiento | Z8: % de cumplimiento
B9: Aerolíneas Auto | C9: 22 | E9: 236 | F9: 10 | G9: 2 | H9: =+E9+I9 -> 259 | I9: 23 | J9: 201 | K9: 14 | L9: 5 | M9: =N9+J9 -> 216 | N9: 15 | O9: 188 | P9: 7 | Q9: 1 | R9: =+O9+S9 -> 218 | S9: 30 | T9: 194 | U9: 4 | V9: 2 | W9: =+T9+X9 -> 216 | X9: 22 | Y9: =+G9+L9+Q9+V9 -> 10 | Z9: =+Y9/(C9+D9) -> 0.45454545
C11: Solicitud Nuevos | D11: Solicitud Reconectados | E11: Activas | F11: Bolsa | G11: nuevos | H11: Total | I11: congelas | J11: Activas | K11: Bolsa | L11: Nuevos | N11: congelas | O11: Activas | P11: bolsa | Q11: nuevo | R11: Total | S11: congelas | T11: Activas | U11: Bolsa | V11: Nuevos | W11: Total | X11: congelas | Y11: Total cumplimiento | Z11: % de cumplimiento
B12: Ciudad | C12: 30 | E12: 306 | F12: 26 | G12: 8 | H12: =+E12+I12 -> 344 | I12: 38 | J12: 301 | K12: 25 | L12: 6 | M12: =+J12+N12 -> 350 | N12: 49 | O12: 294 | P12: 15 | Q12: 5 | R12: =+O12+S12 -> 352 | S12: 58 | T12: 291 | U12: 21 | V12: 7 | W12: =+T12+X12 -> 307 | X12: 16 | Y12: =+G12+L12+Q12+V12 -> 26 | Z12: =+Y12/(C12+D12) -> 0.86666667
B14: Plazas | C14: Solicitud Nuevos | D14: Solicitud Reconectados | E14: Activas | F14: Bolsa | G14: nuevos | H14: Total | I14: congelas | J14: Activas | K14: Bolsa | L14: Nuevos | M14: Total | N14: congelas | O14: Activas | P14: bolsa | Q14: nuevo | R14: Total | S14: congelas | T14: Activas | U14: Bolsa | V14: Nuevos | W14: Total | X14: congelas | Y14: Total cumplimiento | Z14: % de cumplimiento
B15: Jockey | C15: 5 | E15: 77 | F15: 1 | G15: 1 | H15: =+E15+I15 -> 77 | I15: 0 | J15: 79 | K15: 2 | L15: 1 | M15: =+J15+N15 -> 79 | N15: 0 | O15: 80 | P15: 1 | Q15: 0 | R15: =+O15+S15 -> 80 | S15: 0 | T15: 80 | U15: 1 | V15: 0 | W15: =+T15+X15 -> 80 | X15: 0 | Y15: =+G15+L15+Q15+V15 -> 2 | Z15: =+Y15/(C15+D15) -> 0.4
B16: Bellavista | C16: 2 | E16: 37 | H16: =+E16+I16 -> 37 | I16: 0 | J16: 37 | M16: =+J16+N16 -> 37 | N16: 0 | O16: 36 | R16: =+O16+S16 -> 36 | S16: 0 | T16: 38 | W16: =+T16+X16 -> 38 | X16: 0 | Y16: =+G16+L16+Q16+V16 -> 0 | Z16: =+Y16/(C16+D16) -> 0
B17: Total flota | E17: =SUM(E15:E16) -> 114 | F17: =+F15+F16 -> 1 | G17: =SUM(G15:G16) -> 1 | H17: =SUM(H15:H16) -> 114 | I17: =SUM(I15:I16) -> 0 | J17: =SUM(J15:J16) -> 116 | K17: =SUM(K15:K16) -> 2 | L17: =SUM(L15:L16) -> 1 | M17: =SUM(M15:M16) -> 116 | N17: =SUM(N15:N16) -> 0 | O17: =+O15+O16 -> 116 | P17: =SUM(P15:P16) -> 1 | Q17: =SUM(Q15:Q16) -> 0 | R17: =R15+R16 -> 116 | T17: =+T15+T16 -> 118 | U17: =SUM(U15:U16) -> 1 | V17: 0 | W17: =W15+W16 -> 118
Y19: 17
Y20: 10
Y21: 26
Y22: 2

Sheet OCTUBRE
B2: Afiliación | C2: Ope proy | E2: 06/10/2025 - Sem 41 | J2: 13/10/2025 - Sem 42 | O2: 20/10/2025 - Sem 43 | T2: 27/10/2025 - Sem 44
C3: Solicitud Nuevos | D3: Solicitud Reconectados | E3: Activas | F3: Bolsa | G3: nuevos | H3: Total | I3: congelas | J3: Activas | K3: Bolsa | L3: Nuevos | M3: Total | N3: congelas | O3: Activas | P3: Bolsa | Q3: Nuevos | R3: Total | S3: congelas | T3: Activas | U3: Bolsa | V3: Nuevos | W3: Total | X3: congelas | Y3: Total cumplimiento | Z3: % de cumplimiento
B4: Aeropuerto Auto | C4: 52 | E4: 287 | F4: 10 | G4: 5 | H4: =+I4+E4 -> 303 | I4: 16 | J4: 321 | K4: 12 | L4: 1 | M4: =+N4+J4 -> 348 | N4: 27 | O4: 280 | P4: 10 | Q4: 4 | R4: =+S4+O4 -> 293 | S4: 13 | T4: 282 | U4: 13 | V4: 2 | W4: =+X4+T4 -> 293 | X4: 11 | Y4: =+G4+L4+Q4+V4 -> 12 | Z4: =+Y4/(C4+D4) -> 0.23076923
B5: Aeropuerto Van | C5: 9 | E5: 34 | H5: =+E5+I5 -> 36 | I5: 2 | M5: =+J5+N5 -> 0 | O5: 33 | R5: =+O5+S5 -> 48 | S5: 15 | T5: 32 | V5: 1 | W5: =+T5+X5 -> 48 | X5: 16 | Y5: =+G5+L5+Q5+V5 -> 1 | Z5: =+Y5/(C5+D5) -> 0.11111111
B6: Total Flota | E6: =E4+E5 -> 321 | F6: =+F4+F5 -> 10 | G6: =G4+G5 -> 5 | H6: =+H4+H5 -> 339 | I6: =+I4+I5 -> 18 | J6: =+J4+J5 -> 321 | K6: =SUM(K4:K5) -> 12 | L6: =SUM(L4:L5) -> 1 | M6: =+M4+M5 -> 348 | N6: =+N4+N5 -> 27 | O6: =+O4+O5 -> 313 | P6: =SUM(P4:P5) -> 10 | Q6: =SUM(Q4:Q5) -> 4 | R6: =+R4+R5 -> 341 | S6: =+S4+S5 -> 28 | T6: =+T4+T5 -> 314 | U6: =SUM(U4:U5) -> 13 | V6: =+V4+V5 -> 3 | W6: =+W4+W5 -> 341 | X6: =+X4+X5 -> 27
C8: Solicitud Nuevos | D8: Solicitud Reconectados | E8: Activas | F8: Bolsa | G8: nuevos | H8: Total | I8: congelas | J8: Activas | K8: Bolsa | L8: Nuevos | M8: Total | N8: congelas | O8: Activas | P8: bolsa | Q8: nuevo | R8: Total | S8: congelas | T8: Activas | U8: Bolsa | V8: Nuevos | W8: Total | X8: congelas | Y8: Total cumplimiento | Z8: % de cumplimiento
B9: Aerolíneas Auto | C9: 26 | E9: 196 | F9: 11 | G9: 5 | H9: =+E9+I9 -> 215 | I9: 19 | J9: 192 | K9: 13 | L9: 8 | M9: =N9+J9 -> 217 | N9: 25 | O9: 201 | P9: 14 | Q9: 7 | R9: =+O9+S9 -> 228 | S9: 27 | T9: 196 | U9: 11 | V9: 3 | W9: =+T9+X9 -> 221 | X9: 25 | Y9: =+G9+L9+Q9+V9 -> 23 | Z9: =+Y9/(C9+D9) -> 0.88461538
C11: Solicitud Nuevos | D11: Solicitud Reconectados | E11: Activas | F11: Bolsa | G11: nuevos | H11: Total | I11: congelas | J11: Activas | K11: Bolsa | L11: Nuevos | M11: Total | N11: congelas | O11: Activas | P11: bolsa | Q11: nuevo | R11: Total | S11: congelas | T11: Activas | U11: Bolsa | V11: Nuevos | W11: Total | X11: congelas | Y11: Total cumplimiento | Z11: % de cumplimiento
B12: Ciudad | C12: 33 | E12: 283 | F12: 19 | G12: 8 | H12: =+E12+I12 -> 332 | I12: 49 | J12: 279 | K12: 17 | L12: 6 | M12: =+J12+N12 -> 329 | N12: 50 | O12: 281 | P12: 20 | Q12: 6 | R12: =+O12+S12 -> 332 | S12: 51 | T12: 281 | U12: 27 | V12: 12 | W12: =+T12+X12 -> 330 | X12: 49 | Y12: =+G12+L12+Q12+V12 -> 32 | Z12: =+Y12/(C12+D12) -> 0.96969697
B14: Plazas | C14: Solicitud Nuevos | D14: Solicitud Reconectados | E14: Activas | F14: Bolsa | G14: nuevos | H14: Total | I14: congelas | J14: Activas | K14: Bolsa | L14: Nuevos | M14: Total | N14: congelas | O14: Activas | P14: bolsa | Q14: nuevo | R14: Total | S14: congelas | T14: Activas | U14: Bolsa | V14: Nuevos | W14: Total | X14: congelas | Y14: Total cumplimiento | Z14: % de cumplimiento
B15: Jockey | C15: 4 | E15: 78 | F15: 0 | G15: 0 | H15: =+E15+I15 -> 78 | J15: 78 | K15: 0 | L15: 0 | M15: =+J15+N15 -> 78 | N15: 0 | O15: 78 | P15: 1 | R15: =+O15+S15 -> 78 | S15: 0 | T15: 76 | U15: 2 | V15: 2 | W15: =+T15+X15 -> 76 | X15: 0 | Y15: =+G15+L15+Q15+V15 -> 2 | Z15: =+Y15/(C15+D15) -> 0.5
B16: Bellavista | C16: 1 | E16: 35 | F16: 0 | G16: 0 | H16: =+E16+I16 -> 35 | J16: 35 | K16: 0 | M16: =+J16+N16 -> 35 | N16: 0 | O16: 33 | R16: =+O16+S16 -> 33 | S16: 0 | T16: 33 | W16: =+T16+X16 -> 33 | X16: 0 | Y16: =+G16+L16+Q16+V16 -> 0 | Z16: =+Y16/(C16+D16) -> 0
B17: Total flota | E17: =SUM(E15:E16) -> 113 | F17: =+F15+F16 -> 0 | G17: =SUM(G15:G16) -> 0 | H17: =SUM(H15:H16) -> 113 | I17: =SUM(I15:I16) -> 0 | J17: =SUM(J15:J16) -> 113 | K17: =SUM(K15:K16) -> 0 | L17: =SUM(L15:L16) -> 0 | M17: =SUM(M15:M16) -> 113 | N17: =SUM(N15:N16) -> 0 | O17: =+O15+O16 -> 111 | P17: =SUM(P15:P16) -> 1 | Q17: =SUM(Q15:Q16) -> 0 | R17: =R15+R16 -> 111 | T17: =+T15+T16 -> 109 | U17: =SUM(U15:U16) -> 2 | V17: 0 | W17: =W15+W16 -> 109
Y21: =+Y4+Y9+Y12+Y15 -> 69

Sheet SEPTIEMBRE
B2: Afiliación | C2: Ope proy | E2: 01/09/2025 - Sem 36 | J2: 08/09/2025 - Sem 37 | O2: 15/09/2025 - Sem 38 | T2: 22/09/2025 - Sem 39 | Y2: 29/09/2025 - Sem 40
C3: Solicitud Nuevos | D3: Solicitud Reconectados | E3: Activas | F3: Bolsa | G3: nuevos | H3: Total | I3: congelas | J3: Activas | K3: Bolsa | L3: Nuevos | M3: Total | N3: congelas | O3: Activas | P3: Bolsa | Q3: Nuevos | R3: Total | S3: congelas | T3: Activas | U3: Bolsa | V3: Nuevos | W3: Total | X3: congelas | Y3: Activas | Z3: Bolsa | AA3: nuevos | AB3: Total | AC3: congelas | AD3: Total cumplimiento | AE3: % de cumplimiento
B4: Aeropuerto Auto | C4: 76 | E4: 284 | F4: 28 | G4: 10 | H4: =+I4+E4 -> 308 | I4: 24 | J4: 270 | K4: 18 | L4: 9 | M4: =+N4+J4 -> 310 | N4: 40 | O4: 282 | P4: 20 | Q4: 13 | R4: =+S4+O4 -> 296 | S4: 14 | T4: 279 | U4: 18 | V4: 12 | W4: =+X4+T4 -> 305 | X4: 26 | Y4: 288 | Z4: 11 | AA4: 6 | AB4: =+AC4+Y4 -> 303 | AC4: 15 | AD4: =+G4+L4+Q4+V4+AA4 -> 50 | AE4: =+AD4/(C4+D4) -> 0.65789474
B5: Aeropuerto Van | C5: 9 | E5: 28 | H5: =+E5+I5 -> 29 | I5: 1 | J5: 27 | M5: =+J5+N5 -> 28 | N5: 1 | O5: 24 | R5: =+O5+S5 -> 25 | S5: 1 | T5: 24 | W5: =+T5+X5 -> 25 | X5: 1 | Y5: 28 | AB5: =+Y5+AC5 -> 29 | AC5: 1 | AD5: =+G5+L5+Q5+V5+AA5 -> 0 | AE5: =+AD5/(C5+D5) -> 0
B6: Total Flota | E6: =E4+E5 -> 312 | F6: =+F4+F5 -> 28 | G6: =G4+G5 -> 10 | H6: =+H4+H5 -> 337 | I6: =+I4+I5 -> 25 | J6: =+J4+J5 -> 297 | K6: =SUM(K4:K5) -> 18 | L6: =SUM(L4:L5) -> 9 | M6: =+M4+M5 -> 338 | N6: =+N4+N5 -> 41 | O6: =+O4+O5 -> 306 | P6: =SUM(P4:P5) -> 20 | Q6: =SUM(Q4:Q5) -> 13 | R6: =+R4+R5 -> 321 | S6: =+S4+S5 -> 15 | T6: =+T4+T5 -> 303 | U6: =SUM(U4:U5) -> 18 | V6: =+V4+V5 -> 12 | W6: =+W4+W5 -> 330 | X6: =+X4+X5 -> 27 | Y6: =Y4+Y5 -> 316 | Z6: =+Z4+Z5 -> 11 | AA6: =AA4+AA5 -> 6 | AB6: =+AB4+AB5 -> 332 | AC6: =+AC4+AC5 -> 16
C8: Solicitud Nuevos | D8: Solicitud Reconectados | E8: Activas | F8: Bolsa | G8: nuevos | H8: Total | I8: congelas | J8: Activas | K8: Bolsa | L8: Nuevos | M8: Total | N8: congelas | O8: Activas | P8: bolsa | Q8: nuevo | R8: Total | S8: congelas | T8: Activas | U8: Bolsa | V8: Nuevos | W8: Total | X8: congelas | Y8: Activas | Z8: Bolsa | AA8: nuevos | AB8: Total | AC8: congelas | AD8: Total cumplimiento | AE8: % de cumplimiento
B9: Aerolíneas Auto | C9: 26 | E9: 182 | F9: 11 | G9: 3 | H9: =+E9+I9 -> 210 | I9: 28 | J9: 184 | K9: 6 | L9: 2 | M9: =N9+J9 -> 204 | N9: 20 | O9: 184 | P9: 8 | Q9: 0 | R9: =+O9+S9 -> 210 | S9: 26 | T9: 191 | U9: 5 | V9: 8 | W9: =+T9+X9 -> 211 | X9: 20 | Y9: 191 | Z9: 9 | AA9: 5 | AB9: =+Y9+AC9 -> 210 | AC9: 19 | AD9: =+G9+L9+Q9+V9+AA9 -> 18 | AE9: =+AD9/(C9+D9) -> 0.69230769
C11: Solicitud Nuevos | D11: Solicitud Reconectados | E11: Activas | F11: Bolsa | G11: nuevos | H11: Total | I11: congelas | J11: Activas | K11: Bolsa | L11: Nuevos | M11: Total | N11: congelas | O11: Activas | P11: bolsa | Q11: nuevo | R11: Total | S11: congelas | T11: Activas | U11: Bolsa | V11: Nuevos | W11: Total | X11: congelas | Y11: Activas | Z11: Bolsa | AA11: nuevos | AB11: Total | AC11: congelas | AD11: Total cumplimiento | AE11: % de cumplimiento
B12: Ciudad | C12: 40 | E12: 273 | F12: 26 | G12: 4 | H12: =+E12+I12 -> 318 | I12: 45 | J12: 283 | K12: 21 | L12: 4 | M12: =+J12+N12 -> 330 | N12: 47 | O12: 286 | P12: 15 | Q12: 5 | R12: =+O12+S12 -> 330 | S12: 44 | T12: 292 | U12: 14 | V12: 4 | W12: =+T12+X12 -> 335 | X12: 43 | Y12: 277 | Z12: 21 | AA12: 10 | AB12: =+Y12+AC12 -> 330 | AC12: 53 | AD12: =+G12+L12+Q12+V12+AA12 -> 27 | AE12: =+AD12/(C12+D12) -> 0.675
B14: Plazas | C14: Solicitud Nuevos | D14: Solicitud Reconectados | E14: Activas | F14: Bolsa | G14: nuevos | H14: Total | I14: congelas | J14: Activas | K14: Bolsa | L14: Nuevos | M14: Total | N14: congelas | O14: Activas | P14: bolsa | Q14: nuevo | R14: Total | S14: congelas | T14: Activas | U14: Bolsa | V14: Nuevos | W14: Total | X14: congelas | Y14: Activas | Z14: Bolsa | AA14: nuevos | AB14: Total | AC14: congelas | AD14: Total cumplimiento | AE14: % de cumplimiento
B15: Jockey | C15: 4 | E15: 76 | F15: 1 | H15: =+E15+I15 -> 76 | I15: 0 | J15: 76 | K15: 1 | L15: 1 | M15: =+J15+N15 -> 76 | N15: 0 | O15: 77 | P15: 1 | Q15: 1 | R15: =+O15+S15 -> 77 | T15: 77 | U15: 2 | W15: =+T15+X15 -> 77 | X15: 0 | Y15: 77 | Z15: 1 | AA15: 1 | AB15: =+Y15+AC15 -> 77 | AC15: 0 | AD15: =+G15+L15+Q15+V15+AA15 -> 3 | AE15: =+AD15/(C15+D15) -> 0.75
B16: Bellavista | C16: 1 | E16: 34 | F16: 0 | G16: 1 | H16: =+E16+I16 -> 34 | I16: 0 | J16: 35 | M16: =+J16+N16 -> 35 | N16: 0 | O16: 35 | R16: =+O16+S16 -> 35 | T16: 35 | U16: 1 | W16: =+T16+X16 -> 35 | X16: 0 | Y16: 37 | AB16: =+Y16+AC16 -> 37 | AC16: 0 | AD16: =+G16+L16+Q16+V16+AA16 -> 1 | AE16: =+AD16/(C16+D16) -> 1
B17: Total flota | E17: =SUM(E15:E16) -> 110 | F17: =+F15+F16 -> 1 | G17: =SUM(G15:G16) -> 1 | H17: =SUM(H15:H16) -> 110 | I17: =SUM(I15:I16) -> 0 | J17: =SUM(J15:J16) -> 111 | K17: =SUM(K15:K16) -> 1 | L17: =SUM(L15:L16) -> 1 | M17: =SUM(M15:M16) -> 111 | N17: =SUM(N15:N16) -> 0 | P17: =SUM(P15:P16) -> 1 | Q17: =SUM(Q15:Q16) -> 1 | R17: =R15+R16 -> 112 | U17: =SUM(U15:U16) -> 3 | V17: 0 | W17: =W15+W16 -> 112 | Y17: =SUM(Y15:Y16) -> 114 | Z17: =+Z15+Z16 -> 1 | AA17: =SUM(AA15:AA16) -> 1 | AB17: =SUM(AB15:AB16) -> 114 | AC17: =SUM(AC15:AC16) -> 0
AD20: =+AD4+AD9+AD12+AD15 -> 98

Sheet AGOSTO
B2: Afiliación | C2: Ope proy | E2: 01/12/2025 - Sem 32 | J2: 11/08/2025 - Sem 33 | O2: 18/08/2025 - Sem 34 | T2: 25/08/2025 - Sem 35
C3: Solicitud Nuevos | D3: Solicitud Reconectados | E3: Activas | F3: Bolsa | G3: nuevos | H3: Total | I3: congelas | J3: Activas | K3: Bolsa | L3: Nuevos | M3: Total | N3: congelas | O3: Activas | P3: Bolsa | Q3: Nuevos | R3: Total | S3: congelas | T3: Activas | U3: Bolsa | V3: Nuevos | W3: Total | X3: congelas | Y3: Total cumplimiento | Z3: % de cumplimiento
B4: Aeropuerto Auto | C4: 30 | E4: 243 | F4: 21 | G4: 7 | H4: =+I4+E4 -> 290 | I4: 47 | J4: 257 | K4: 28 | L4: 7 | M4: =+N4+J4 -> 290 | N4: 33 | O4: 254 | P4: 25 | Q4: 13 | R4: =+S4+O4 -> 289 | S4: 35 | T4: 275 | U4: 35 | V4: 15 | W4: =+X4+T4 -> 298 | X4: 23 | Y4: =+G4+L4+Q4+V4 -> 42 | Z4: =+Y4/(C4+D4) -> 1.4
B5: Aeropuerto Van | E5: 30 | H5: =+E5+I5 -> 33 | I5: 3 | J5: 29 | M5: =+J5+N5 -> 31 | N5: 2 | O5: 28 | R5: =+O5+S5 -> 30 | S5: 2 | T5: 27 | W5: =+T5+X5 -> 29 | X5: 2 | Y5: =+G5+L5+Q5+V5 -> 0 | Z5: =+Y5/(C5+D5) -> #DIV/0!
B6: Total Flota | E6: =E4+E5 -> 273 | F6: =+F4+F5 -> 21 | G6: =G4+G5 -> 7 | H6: =+H4+H5 -> 323 | I6: =+I4+I5 -> 50 | J6: =+J4+J5 -> 286 | K6: =SUM(K4:K5) -> 28 | L6: =SUM(L4:L5) -> 7 | M6: =+M4+M5 -> 321 | N6: =+N4+N5 -> 35 | O6: =+O4+O5 -> 282 | P6: =SUM(P4:P5) -> 25 | Q6: =SUM(Q4:Q5) -> 13 | R6: =+R4+R5 -> 319 | S6: =+S4+S5 -> 37 | T6: =+T4+T5 -> 302 | U6: =SUM(U4:U5) -> 35 | V6: =+V4+V5 -> 15 | W6: =+W4+W5 -> 327 | X6: =+X4+X5 -> 25
C8: Solicitud Nuevos | D8: Solicitud Reconectados | E8: Activas | F8: Bolsa | G8: nuevos | H8: Total | I8: congelas | J8: Activas | K8: Bolsa | L8: Nuevos | M8: Total | N8: congelas | O8: Activas | P8: bolsa | Q8: nuevo | R8: Total | S8: congelas | T8: Activas | U8: Bolsa | V8: Nuevos | W8: Total | X8: congelas | Y8: Total cumplimiento | Z8: % de cumplimiento
B9: Aerolíneas Auto | C9: 12 | E9: 158 | F9: 24 | G9: 9 | H9: =+E9+I9 -> 182 | I9: 24 | J9: 177 | K9: 21 | L9: 7 | M9: =N9+J9 -> 195 | N9: 18 | O9: 182 | P9: 14 | Q9: 6 | R9: =+O9+S9 -> 199 | S9: 17 | T9: 179 | U9: 15 | V9: 5 | W9: =+T9+X9 -> 206 | X9: 27 | Y9: =+G9+L9+Q9+V9 -> 27 | Z9: =+Y9/(C9+D9) -> 2.25
C11: Solicitud Nuevos | D11: Solicitud Reconectados | E11: Activas | F11: Bolsa | G11: nuevos | H11: Total | I11: congelas | J11: Activas | K11: Bolsa | L11: Nuevos | M11: Total | N11: congelas | O11: Activas | P11: bolsa | Q11: nuevo | R11: Total | S11: congelas | T11: Activas | U11: Bolsa | V11: Nuevos | W11: Total | X11: congelas | Y11: Total cumplimiento | Z11: % de cumplimiento
B12: Ciudad | C12: 30 | E12: 250 | F12: 23 | G12: 4 | H12: =+E12+I12 -> 298 | I12: 48 | J12: 257 | K12: 23 | L12: 8 | M12: =+J12+N12 -> 303 | N12: 46 | O12: 268 | P12: 16 | Q12: 7 | R12: =+O12+S12 -> 308 | S12: 40 | T12: 278 | U12: 21 | V12: 5 | W12: =+T12+X12 -> 309 | X12: 31 | Y12: =+G12+L12+Q12+V12 -> 24 | Z12: =+Y12/(C12+D12) -> 0.8
B14: Plazas | C14: Solicitud Nuevos | D14: Solicitud Reconectados | E14: Activas | F14: Bolsa | G14: nuevos | H14: Total | I14: congelas | J14: Activas | K14: Bolsa | L14: Nuevos | M14: Total | N14: congelas | O14: Activas | P14: bolsa | Q14: nuevo | R14: Total | S14: congelas | T14: Activas | U14: Bolsa | V14: Nuevos | W14: Total | X14: congelas | Y14: Total cumplimiento | Z14: % de cumplimiento
B15: Jockey | C15: 3 | E15: 77 | F15: 3 | H15: =+E15+I15 -> 77 | I15: 0 | J15: 77 | K15: 3 | L15: 2 | M15: =+J15+N15 -> 77 | N15: 0 | O15: 78 | P15: 2 | Q15: 1 | R15: =+O15+S15 -> 78 | S15: 0 | T15: 77 | U15: 0 | W15: =+T15+X15 -> 77 | X15: 0 | Y15: =+G15+L15+Q15+V15 -> 3 | Z15: =+Y15/(C15+D15) -> 1
B16: Bellavista | C16: 1 | E16: 34 | F16: 1 | H16: =+E16+I16 -> 34 | I16: 0 | J16: 33 | M16: =+J16+N16 -> 33 | N16: 0 | O16: 35 | R16: =+O16+S16 -> 35 | S16: 0 | T16: 35 | W16: =+T16+X16 -> 35 | X16: 0 | Y16: =+G16+L16+Q16+V16 -> 0 | Z16: =+Y16/(C16+D16) -> 0
B17: Total flota | E17: =SUM(E15:E16) -> 111 | F17: =+F15+F16 -> 4 | G17: =SUM(G15:G16) -> 0 | H17: =SUM(H15:H16) -> 111 | I17: =SUM(I15:I16) -> 0 | J17: =SUM(J15:J16) -> 110 | K17: =SUM(K15:K16) -> 3 | L17: =SUM(L15:L16) -> 2 | M17: =SUM(M15:M16) -> 110 | N17: =SUM(N15:N16) -> 0 | P17: =SUM(P15:P16) -> 2 | Q17: =SUM(Q15:Q16) -> 1 | R17: =R15+R16 -> 113 | U17: =SUM(U15:U16) -> 0 | V17: 0 | W17: =W15+W16 -> 112
Y22: =+Y4+Y9+Y12+Y15 -> 96

Sheet JULIO
B2: Afiliación | C2: Ope proy | E2: 07/07/2025 - Sem 28 | J2: 14/07/2025 - Sem 29 | O2: 21/07/2025 - Sem30 | T2: 28/07/2025 - Sem 31
C3: Solicitud Nuevos | D3: Solicitud Reconectados | E3: Activas | F3: Bolsa | G3: nuevos | H3: Total | I3: congelas | J3: Activas | K3: Bolsa | L3: Nuevos | M3: Total | N3: congelas | O3: Activas | P3: Bolsa | Q3: Nuevos | R3: Total | S3: congelas | T3: Activas | U3: Bolsa | V3: Nuevos | W3: Total | X3: congelas | Y3: Total cumplimiento | Z3: % de cumplimiento
B4: Aeropuerto Auto | C4: 74 | E4: 244 | F4: 11 | G4: 3 | H4: =+I4+E4 -> 290 | I4: 46 | J4: 258 | K4: 25 | L4: 12 | M4: =+N4+J4 -> 296 | N4: 38 | O4: 268 | P4: 9 | Q4: 3 | R4: =+S4+O4 -> 354 | S4: 86 | T4: 257 | U4: 25 | V4: 10 | W4: =+X4+T4 -> 299 | X4: 42 | Y4: =+G4+L4+Q4+V4 -> 28 | Z4: =+Y4/(C4+D4) -> 0.37837838
B5: Aeropuerto Van | C5: 4 | E5: 35 | F5: 1 | G5: 1 | H5: =+E5+I5 -> 37 | I5: 2 | J5: 35 | M5: =+J5+N5 -> 39 | N5: 4 | O5: 35 | R5: =+O5+S5 -> 39 | S5: 4 | T5: 28 | W5: =+T5+X5 -> 32 | X5: 4 | Y5: =+G5+L5+Q5+V5 -> 1 | Z5: =+Y5/(C5+D5) -> 0.25
B6: Total Flota | E6: =E4+E5 -> 279 | F6: =+F4+F5 -> 12 | G6: =G4+G5 -> 4 | H6: =+H4+H5 -> 327 | I6: =+I4+I5 -> 48 | J6: =+J4+J5 -> 293 | K6: =SUM(K4:K5) -> 25 | L6: =SUM(L4:L5) -> 12 | M6: =+M4+M5 -> 335 | N6: =+N4+N5 -> 42 | O6: =+O4+O5 -> 303 | P6: =SUM(P4:P5) -> 9 | Q6: =SUM(Q4:Q5) -> 3 | R6: =+R4+R5 -> 393 | S6: =+S4+S5 -> 90 | T6: =+T4+T5 -> 285 | U6: =SUM(U4:U5) -> 25 | V6: =+V4+V5 -> 10 | W6: =+W4+W5 -> 331 | X6: =+X4+X5 -> 46
C8: Solicitud Nuevos | D8: Solicitud Reconectados | E8: Activas | F8: Bolsa | G8: nuevos | H8: Total | I8: congelas | J8: Activas | K8: Bolsa | L8: Nuevos | M8: Total | N8: congelas | O8: Activas | P8: bolsa | Q8: nuevo | R8: Total | S8: congelas | T8: Activas | U8: Bolsa | V8: Nuevos | W8: Total | X8: congelas | Y8: Total cumplimiento | Z8: % de cumplimiento
B9: Aerolíneas Auto | C9: 34 | E9: 151 | F9: 8 | G9: 4 | H9: =+E9+I9 -> 168 | I9: 17 | J9: 159 | K9: 14 | L9: 6 | M9: =N9+J9 -> 170 | N9: 11 | O9: 161 | P9: 14 | Q9: 6 | R9: =+O9+S9 -> 179 | S9: 18 | T9: 166 | U9: 16 | W9: =+T9+X9 -> 188 | X9: 22 | Y9: =+G9+L9+Q9+V9 -> 16 | Z9: =+Y9/(C9+D9) -> 0.47058824
C11: Solicitud Nuevos | D11: Solicitud Reconectados | E11: Activas | F11: Bolsa | G11: nuevos | H11: Total | I11: congelas | J11: Activas | K11: Bolsa | L11: Nuevos | M11: Total | N11: congelas | O11: Activas | P11: bolsa | Q11: nuevo | R11: Total | S11: congelas | T11: Activas | U11: Bolsa | V11: Nuevos | W11: Total | X11: congelas | Y11: Total cumplimiento | Z11: % de cumplimiento
B12: Ciudad | C12: 26 | E12: 271 | F12: 15 | G12: 4 | H12: =+E12+I12 -> 321 | I12: 50 | J12: 266 | K12: 16 | L12: 8 | M12: =+J12+N12 -> 315 | N12: 49 | O12: 276 | P12: 11 | Q12: 5 | R12: =+O12+S12 -> 312 | S12: 36 | T12: 252 | U12: 17 | W12: =+T12+X12 -> 293 | X12: 41 | Y12: =+G12+L12+Q12+V12 -> 17 | Z12: =+Y12/(C12+D12) -> 0.65384615
B14: Plazas | C14: Solicitud Nuevos | D14: Solicitud Reconectados | E14: Activas | F14: Bolsa | G14: nuevos | H14: Total | I14: congelas | J14: Activas | K14: Bolsa | L14: Nuevos | M14: Total | N14: congelas | O14: Activas | P14: bolsa | Q14: nuevo | R14: Total | S14: congelas | T14: Activas | U14: Bolsa | V14: Nuevos | W14: Total | X14: congelas | Y14: Total cumplimiento | Z14: % de cumplimiento
B15: Jockey | C15: 4 | E15: 78 | F15: 2 | G15: 0 | H15: =+E15+I15 -> 78 | I15: 0 | J15: 78 | K15: 2 | L15: 0 | M15: =+J15+N15 -> 78 | N15: 0 | O15: 78 | P15: 1 | Q15: 0 | R15: =+O15+S15 -> 78 | S15: 0 | T15: 77 | U15: 2 | W15: =+T15+X15 -> 77 | X15: 0 | Y15: =+G15+L15+Q15+V15 -> 0 | Z15: =+Y15/(C15+D15) -> 0
E16: 27 | F16: 0 | G16: 0 | H16: =+E16+I16 -> 27 | I16: 0 | J16: 24 | M16: =+J16+N16 -> 24 | N16: 0 | O16: 24 | P16: 0 | Q16: 0 | R16: =+O16+S16 -> 24 | S16: 0 | W16: =+T16+X16 -> 0 | X16: 0 | Y16: =+G16+L16+Q16+V16 -> 0 | Z16: =+Y16/(C16+D16) -> #DIV/0!
B17: Bellavista | C17: 3 | E17: 35 | F17: 0 | G17: 0 | H17: =+E17+I17 -> 35 | I17: 0 | J17: 35 | K17: 0 | L17: 0 | M17: =+J17+N17 -> 35 | N17: 0 | O17: 35 | P17: 0 | Q17: 0 | R17: =+O17+S17 -> 35 | S17: 0 | T17: 33 | U17: 1 | W17: =+T17+X17 -> 33 | X17: 0 | Y17: =+G17+L17+Q17+V17 -> 0 | Z17: =+Y17/(C17+D17) -> 0
E18: 5 | F18: 0 | G18: 0 | H18: =+E18+I18 -> 5 | I18: 0 | J18: 5 | K18: 0 | L18: 0 | M18: =+J18+N18 -> 5 | N18: 0 | O18: 0 | P18: 0 | Q18: 0 | R18: =+O18+S18 -> 0 | S18: 0 | W18: =+T18+X18 -> 0 | X18: 0 | Y18: =+G18+L18+Q18+V18 -> 0 | Z18: =+Y18/(C18+D18) -> #DIV/0!
B19: Total flota | E19: =SUM(E15:E18) -> 145 | F19: =+F15+F16+F17+F18 -> 2 | G19: =SUM(G15:G18) -> 0 | H19: =SUM(H15:H18) -> 145 | I19: =SUM(I15:I18) -> 0 | J19: =SUM(J15:J18) -> 142 | K19: =SUM(K15:K18) -> 2 | L19: =SUM(L15:L18) -> 0 | M19: =SUM(M15:M18) -> 142 | N19: =SUM(N15:N18) -> 0 | P19: =SUM(P15:P18) -> 1 | Q19: =SUM(Q15:Q18) -> 0 | U19: =SUM(U15:U18) -> 3 | V19: 0
Y22: =+Y4+Y9+Y12 -> 61

Sheet JUNIO
B2: Afiliación | C2: Ope proy | E2: 02/06/2025 - Sem 21 | J2: 09/06/2025 - Sem 22 | O2: 16/06/2025 - Sem 23 | T2: 23/06/2025 - Sem 24 | Y2: 30/06/2025 - Sem 25
C3: Solicitud Nuevos | D3: Solicitud Reconectados | E3: Activas | F3: Bolsa | G3: nuevos | H3: Total | I3: congelas | J3: Activas | K3: Bolsa | L3: Nuevos | M3: Total | N3: congelas | O3: Activas | P3: Bolsa | Q3: Nuevos | R3: Total | S3: congelas | T3: Activas | U3: Bolsa | V3: Nuevos | W3: Total | X3: congelas | Y3: Activas | Z3: Bolsa | AA3: nuevos | AB3: Total | AC3: congelas | AD3: Total cumplimiento | AE3: % de cumplimiento
B4: Aeropuerto Auto | C4: 50 | D4: 6 | E4: 255 | F4: 12 | G4: 8 | H4: =+I4+E4 -> 285 | I4: 30 | J4: 255 | K4: 13 | L4: 5 | M4: =+N4+J4 -> 283 | N4: 28 | O4: 255 | P4: 20 | Q4: 9 | R4: =+S4+O4 -> 284 | S4: 29 | T4: 252 | U4: 24 | V4: 8 | W4: =+X4+T4 -> 285 | X4: 33 | Y4: 251 | Z4: 13 | AA4: 11 | AB4: =+AC4+Y4 -> 287 | AC4: 36 | AD4: =+G4+L4+Q4+V4+AA4 -> 41 | AE4: =+AD4/(C4+D4) -> 0.73214286
B5: Aeropuerto Van | C5: 2 | E5: 31 | F5: 0 | G5: 0 | H5: =+E5+I5 -> 32 | I5: 1 | J5: 32 | K5: 0 | L5: 0 | M5: =+J5+N5 -> 33 | N5: 1 | O5: 31 | P5: 0 | Q5: 0 | R5: =+O5+S5 -> 32 | S5: 1 | T5: 33 | U5: 0 | V5: 0 | W5: =+T5+X5 -> 33 | X5: 0 | Y5: 33 | AB5: =+Y5+AC5 -> 34 | AC5: 1 | AD5: =+G5+L5+Q5+V5+AA5 -> 0 | AE5: =+AD5/(C5+D5) -> 0
B6: Total Flota | E6: =E4+E5 -> 286 | F6: =+F4+F5 -> 12 | G6: =G4+G5 -> 8 | H6: =+H4+H5 -> 317 | I6: =+I4+I5 -> 31 | J6: =+J4+J5 -> 287 | K6: =SUM(K4:K5) -> 13 | L6: =SUM(L4:L5) -> 5 | M6: =+M4+M5 -> 316 | N6: =+N4+N5 -> 29 | O6: =+O4+O5 -> 286 | P6: =SUM(P4:P5) -> 20 | Q6: =SUM(Q4:Q5) -> 9 | R6: =+R4+R5 -> 316 | S6: =+S4+S5 -> 30 | T6: =+T4+T5 -> 285 | U6: =SUM(U4:U5) -> 24 | V6: =+V4+V5 -> 8 | W6: =+W4+W5 -> 318 | X6: =+X4+X5 -> 33 | Y6: =Y4+Y5 -> 284 | Z6: =+Z4+Z5 -> 13 | AA6: =AA4+AA5 -> 11 | AB6: =+AB4+AB5 -> 321 | AC6: =+AC4+AC5 -> 37
C8: Solicitud Nuevos | D8: Solicitud Reconectados | E8: Activas | F8: Bolsa | G8: nuevos | H8: Total | I8: congelas | J8: Activas | K8: Bolsa | L8: Nuevos | M8: Total | N8: congelas | O8: Activas | P8: bolsa | Q8: nuevo | R8: Total | S8: congelas | T8: Activas | U8: Bolsa | V8: Nuevos | W8: Total | X8: congelas | Y8: Activas | Z8: Bolsa | AA8: nuevos | AB8: Total | AC8: congelas | AD8: Total cumplimiento | AE8: % de cumplimiento
B9: Aerolíneas Auto | C9: 9 | D9: 1 | E9: 145 | F9: 5 | G9: 2 | H9: =+E9+I9 -> 154 | I9: 9 | J9: 139 | K9: 6 | L9: 4 | M9: =N9+J9 -> 153 | N9: 14 | O9: 140 | P9: 4 | Q9: 1 | R9: =+O9+S9 -> 157 | S9: 17 | T9: 142 | U9: 4 | V9: 6 | W9: =+T9+X9 -> 166 | X9: 24 | Y9: 147 | Z9: 9 | AA9: 6 | AB9: =+Y9+AC9 -> 164 | AC9: 17 | AD9: =+G9+L9+Q9+V9+AA9 -> 19 | AE9: =+AD9/(C9+D9) -> 1.9
C11: Solicitud Nuevos | D11: Solicitud Reconectados | E11: Activas | F11: Bolsa | G11: nuevos | H11: Total | I11: congelas | J11: Activas | K11: Bolsa | L11: Nuevos | M11: Total | N11: congelas | O11: Activas | P11: bolsa | Q11: nuevo | R11: Total | S11: congelas | T11: Activas | U11: Bolsa | V11: Nuevos | W11: Total | X11: congelas | Y11: Activas | Z11: Bolsa | AA11: nuevos | AB11: Total | AC11: congelas | AD11: Total cumplimiento | AE11: % de cumplimiento
B12: Ciudad | C12: 16 | E12: 274 | F12: 15 | G12: 7 | H12: =+E12+I12 -> 330 | I12: 56 | J12: 271 | K12: 20 | L12: 9 | M12: =+J12+N12 -> 323 | N12: 52 | O12: 310 | P12: 20 | Q12: 9 | R12: =+O12+S12 -> 330 | S12: 20 | T12: 271 | U12: 27 | V12: 8 | W12: =+T12+X12 -> 313 | X12: 42 | Y12: 269 | Z12: 16 | AA12: 8 | AB12: =+Y12+AC12 -> 315 | AC12: 46 | AD12: =+G12+L12+Q12+V12+AA12 -> 41 | AE12: =+AD12/(C12+D12) -> 2.5625
B14: Plazas | C14: Solicitud Nuevos | D14: Solicitud Reconectados | E14: Activas | F14: Bolsa | G14: nuevos | H14: Total | I14: congelas | J14: Activas | K14: Bolsa | L14: Nuevos | M14: Total | N14: congelas | O14: Activas | P14: bolsa | Q14: nuevo | R14: Total | S14: congelas | T14: Activas | U14: Bolsa | V14: Nuevos | W14: Total | X14: congelas | Y14: Activas | Z14: Bolsa | AA14: nuevos | AB14: Total | AC14: congelas | AD14: Total cumplimiento | AE14: % de cumplimiento
B15: Jockey | C15: 2 | E15: 75 | H15: =+E15+I15 -> 75 | I15: 0 | J15: 76 | K15: 0 | L15: 0 | M15: =+J15+N15 -> 76 | N15: 0 | O15: 79 | P15: 0 | Q15: 0 | R15: =+O15+S15 -> 79 | S15: 0 | T15: 80 | U15: 0 | W15: =+T15+X15 -> 80 | X15: 0 | Y15: 79 | Z15: 3 | AA15: 1 | AB15: =+Y15+AC15 -> 79 | AC15: 0 | AD15: =+G15+L15+Q15+V15+AA15 -> 1 | AE15: =+AD15/(C15+D15) -> 0.5
B16: La Marina | C16: 2 | E16: 28 | F16: 0 | G16: 0 | H16: =+E16+I16 -> 28 | I16: 0 | J16: 27 | M16: =+J16+N16 -> 27 | N16: 0 | O16: 27 | P16: 0 | Q16: 0 | R16: =+O16+S16 -> 27 | S16: 0 | T16: 27 | U16: 0 | W16: =+T16+X16 -> 27 | X16: 0 | Y16: 28 | Z16: 0 | AA16: 0 | AB16: =+Y16+AC16 -> 28 | AC16: 0 | AD16: =+G16+L16+Q16+V16+AA16 -> 0 | AE16: =+AD16/(C16+D16) -> 0
B17: Bellavista | C17: 2 | E17: 34 | F17: 0 | G17: 0 | H17: =+E17+I17 -> 34 | I17: 0 | J17: 34 | K17: 0 | L17: 0 | M17: =+J17+N17 -> 34 | N17: 0 | O17: 35 | P17: 0 | Q17: 0 | R17: =+O17+S17 -> 35 | S17: 0 | T17: 33 | U17: 2 | V17: 1 | W17: =+T17+X17 -> 33 | X17: 0 | Y17: 34 | Z17: 0 | AA17: 0 | AB17: =+Y17+AC17 -> 34 | AC17: 0 | AD17: =+G17+L17+Q17+V17+AA17 -> 1 | AE17: =+AD17/(C17+D17) -> 0.5
B18: Angamos | C18: 2 | E18: 5 | F18: 0 | G18: 0 | H18: =+E18+I18 -> 5 | I18: 0 | J18: 5 | K18: 0 | L18: 0 | M18: =+J18+N18 -> 5 | N18: 0 | O18: 5 | P18: 0 | Q18: 0 | R18: =+O18+S18 -> 5 | S18: 0 | T18: 5 | U18: 0 | W18: =+T18+X18 -> 5 | X18: 0 | Y18: 5 | Z18: 0 | AA18: 0 | AB18: =+Y18+AC18 -> 5 | AC18: 0 | AD18: =+G18+L18+Q18+V18+AA18 -> 0 | AE18: =+AD18/(C18+D18) -> 0
B19: Total flota | E19: =SUM(E15:E18) -> 142 | F19: =+F15+F16+F17+F18 -> 0 | G19: =SUM(G15:G18) -> 0 | H19: =SUM(H15:H18) -> 142 | I19: =SUM(I15:I18) -> 0 | K19: =SUM(K15:K18) -> 0 | L19: =SUM(L15:L18) -> 0 | P19: =SUM(P15:P18) -> 0 | Q19: =SUM(Q15:Q18) -> 0 | U19: =SUM(U15:U18) -> 2 | V19: 0 | Y19: =SUM(Y15:Y18) -> 146 | Z19: =+Z15+Z16+Z17+Z18 -> 3 | AA19: =SUM(AA15:AA18) -> 1 | AB19: =SUM(AB15:AB18) -> 146 | AC19: =SUM(AC15:AC18) -> 0

Sheet MAYO
B2: Afiliación | C2: Ope proy | E2: 05/05/2025 - Sem 17 | J2: 12/05/2025 - Sem 18 | O2: 19/05/2025 - Sem 19 | T2: 26/05/2025 - Sem 20
C3: Solicitud Nuevos | D3: Solicitud Reconectados | E3: Activas | F3: Bolsa | G3: nuevos | H3: Total | I3: congelas | J3: Activas | K3: Bolsa | L3: Nuevos | M3: Total | N3: congelas | O3: Activas | P3: Bolsa | Q3: Nuevos | R3: Total | S3: congelas | T3: Activas | U3: Bolsa | V3: Nuevos | W3: Total | X3: congelas | Y3: Total cumplimiento | Z3: % de cumplimiento
B4: Aeropuerto Auto | C4: 46 | E4: 259 | F4: 10 | G4: 6 | H4: =+I4+E4 -> 290 | I4: 31 | J4: 255 | K4: 14 | L4: 3 | M4: =+N4+J4 -> 287 | N4: 32 | O4: 246 | P4: 19 | Q4: 7 | R4: =+S4+O4 -> 275 | S4: 29 | T4: 254 | U4: 13 | V4: 6 | W4: =+X4+T4 -> 282 | X4: 28 | Y4: =+G4+L4+Q4+V4 -> 22 | Z4: =+Y4/(C4+D4) -> 0.47826087
B5: Aeropuerto Van | C5: 10 | E5: 18 | F5: 0 | G5: 0 | H5: =+E5+I5 -> 19 | I5: 1 | J5: 19 | K5: 0 | L5: 0 | M5: =+J5+N5 -> 19 | N5: 0 | O5: 26 | R5: =+O5+S5 -> 26 | S5: 0 | T5: 25 | U5: 0 | W5: =+T5+X5 -> 28 | X5: 3 | Y5: =+G5+L5+Q5+V5 -> 0 | Z5: =+Y5/(C5+D5) -> 0
B6: Total Flota | E6: =E4+E5 -> 277 | F6: =+F4+F5 -> 10 | G6: =G4+G5 -> 6 | H6: =+H4+H5 -> 309 | I6: =+I4+I5 -> 32 | J6: =+J4+J5 -> 274 | K6: =SUM(K4:K5) -> 14 | L6: =SUM(L4:L5) -> 3 | M6: =+M4+M5 -> 306 | N6: =+N4+N5 -> 32 | O6: =+O4+O5 -> 272 | P6: =SUM(P4:P5) -> 19 | Q6: =SUM(Q4:Q5) -> 7 | R6: =+R4+R5 -> 301 | S6: =+S4+S5 -> 29 | T6: =+T4+T5 -> 279 | U6: =SUM(U4:U5) -> 13 | V6: =+V4+V5 -> 6 | W6: =+W4+W5 -> 310 | X6: =+X4+X5 -> 31
C8: Solicitud Nuevos | D8: Solicitud Reconectados | E8: Activas | F8: Bolsa | G8: nuevos | H8: Total | I8: congelas | J8: Activas | K8: Bolsa | L8: Nuevos | M8: Total | N8: congelas | O8: Activas | P8: bolsa | Q8: nuevo | R8: Total | S8: congelas | T8: Activas | U8: Bolsa | V8: Nuevos | W8: Total | X8: congelas | Y8: Total cumplimiento | Z8: % de cumplimiento
B9: Aerolíneas Auto | C9: 13 | E9: 139 | F9: 7 | G9: 4 | H9: =+E9+I9 -> 155 | I9: 16 | J9: 131 | K9: 2 | L9: 1 | M9: =N9+J9 -> 154 | N9: 23 | O9: 137 | P9: 4 | Q9: 2 | R9: =+O9+S9 -> 152 | S9: 15 | T9: 141 | U9: 2 | V9: 0 | W9: =+T9+X9 -> 154 | X9: 13 | Y9: =+G9+L9+Q9+V9 -> 7 | Z9: =+Y9/(C9+D9) -> 0.53846154
C11: Solicitud Nuevos | D11: Solicitud Reconectados | E11: Activas | F11: Bolsa | G11: nuevos | H11: Total | I11: congelas | J11: Activas | K11: Bolsa | L11: Nuevos | M11: Total | N11: congelas | O11: Activas | P11: bolsa | Q11: nuevo | R11: Total | S11: congelas | T11: Activas | U11: Bolsa | V11: Nuevos | W11: Total | X11: congelas | Y11: Total cumplimiento | Z11: % de cumplimiento
B12: Ciudad | C12: 26 | E12: 251 | F12: 15 | G12: 4 | H12: =+E12+I12 -> 325 | I12: 74 | J12: 266 | K12: 23 | L12: 8 | M12: =+J12+N12 -> 323 | N12: 57 | O12: 270 | P12: 17 | Q12: 6 | R12: =+O12+S12 -> 320 | S12: 50 | T12: 273 | U12: 23 | V12: 6 | W12: =+T12+X12 -> 320 | X12: 47 | Y12: =+G12+L12+Q12+V12 -> 24 | Z12: =+Y12/(C12+D12) -> 0.92307692
B14: Plazas | C14: Solicitud Nuevos | D14: Solicitud Reconectados | E14: Activas | F14: Bolsa | G14: nuevos | H14: Total | I14: congelas | J14: Activas | K14: Bolsa | L14: Nuevos | M14: Total | N14: congelas | O14: Activas | P14: bolsa | Q14: nuevo | R14: Total | S14: congelas | T14: Activas | U14: Bolsa | V14: Nuevos | W14: Total | X14: congelas | Y14: Total cumplimiento | Z14: % de cumplimiento
B15: Jockey | C15: 3 | E15: 67 | F15: 1 | G15: 1 | H15: =+E15+I15 -> 70 | I15: 3 | J15: 70 | K15: 0 | L15: 0 | M15: =+J15+N15 -> 72 | N15: 2 | O15: 70 | P15: 0 | Q15: 0 | R15: =+O15+S15 -> 72 | S15: 2 | T15: 72 | U15: 0 | W15: =+T15+X15 -> 74 | X15: 2 | Y15: =+G15+L15+Q15+V15 -> 1 | Z15: =+Y15/(C15+D15) -> 0.33333333
B16: La Marina | C16: 3 | E16: 25 | F16: 0 | G16: 0 | H16: =+E16+I16 -> 25 | I16: 0 | J16: 24 | K16: 1 | L16: 1 | M16: =+J16+N16 -> 24 | N16: 0 | O16: 25 | P16: 0 | Q16: 0 | R16: =+O16+S16 -> 26 | S16: 1 | T16: 25 | U16: 1 | W16: =+T16+X16 -> 26 | X16: 1 | Y16: =+G16+L16+Q16+V16 -> 1 | Z16: =+Y16/(C16+D16) -> 0.33333333
B17: Bellavista | C17: 5 | E17: 25 | F17: 0 | G17: 0 | H17: =+E17+I17 -> 25 | I17: 0 | J17: 35 | K17: 0 | L17: 0 | M17: =+J17+N17 -> 35 | N17: 0 | O17: 34 | P17: 0 | Q17: 0 | R17: =+O17+S17 -> 34 | S17: 0 | T17: 35 | U17: 1 | W17: =+T17+X17 -> 35 | X17: 0 | Y17: =+G17+L17+Q17+V17 -> 0 | Z17: =+Y17/(C17+D17) -> 0
B18: Angamos | C18: 4 | E18: 4 | F18: 0 | G18: 0 | H18: =+E18+I18 -> 4 | I18: 0 | J18: 4 | K18: 0 | L18: 0 | M18: =+J18+N18 -> 4 | N18: 0 | O18: 4 | P18: 0 | Q18: 0 | R18: =+O18+S18 -> 5 | S18: 1 | T18: 4 | U18: 0 | W18: =+T18+X18 -> 5 | X18: 1 | Y18: =+G18+L18+Q18+V18 -> 0 | Z18: =+Y18/(C18+D18) -> 0
B19: Total flota | E19: =SUM(E15:E18) -> 121 | F19: =+F15+F16+F17+F18 -> 1 | G19: =SUM(G15:G18) -> 1 | H19: =SUM(H15:H18) -> 124 | I19: =SUM(I15:I18) -> 3 | K19: =SUM(K15:K18) -> 1 | L19: =SUM(L15:L18) -> 1 | P19: =SUM(P15:P18) -> 0 | Q19: =SUM(Q15:Q18) -> 0 | U19: =SUM(U15:U18) -> 2 | V19: 0

Sheet ABRIL
B2: Afiliación | C2: Ope proy | E2: 7/04/2025 - Sem 13 | J2: 14/04/2025 - Sem 14 | O2: 21/04/2025 - Sem 15 | T2: 28/04/2025 - Sem 16
C3: Solicitud Nuevos | D3: Solicitud Reconectados | E3: Activas | F3: Bolsa | G3: nuevos | H3: Total | I3: congelas | J3: Activas | K3: Bolsa | L3: Nuevos | M3: Total | N3: congelas | O3: Activas | P3: Bolsa | Q3: Nuevos | R3: Total | S3: congelas | T3: Activas | U3: Bolsa | V3: Nuevos | W3: Total | X3: congelas | Y3: Total cumplimiento | Z3: % de cumplimiento
B4: Aeropuerto Auto | C4: 41 | E4: 254 | F4: 7 | G4: 5 | H4: =+I4+E4 -> 283 | I4: 29 | J4: 257 | K4: 13 | L4: 7 | M4: =+N4+J4 -> 287 | N4: 30 | O4: 246 | P4: 10 | Q4: 6 | R4: =+S4+O4 -> 285 | S4: 39 | T4: 245 | U4: 15 | V4: 6 | W4: =+X4+T4 -> 278 | X4: 33 | Y4: =+G4+L4+Q4+V4 -> 24 | Z4: =+Y4/(C4+D4) -> 0.58536585
B5: Aeropuerto Van | C5: 1 | E5: 19 | G5: 0 | H5: =+E5+I5 -> 20 | I5: 1 | J5: 18 | K5: 0 | L5: 0 | M5: =+J5+N5 -> 19 | N5: 1 | O5: 16 | P5: 0 | Q5: 0 | R5: =+O5+S5 -> 19 | S5: 3 | T5: 17 | U5: 0 | V5: 0 | W5: =+T5+X5 -> 18 | X5: 1 | Y5: =+G5+L5+Q5+V5 -> 0 | Z5: =+Y5/(C5+D5) -> 0
B6: Total Flota | E6: =E4+E5 -> 273 | F6: =+F4+F5 -> 7 | G6: =G4+G5 -> 5 | H6: =+H4+H5 -> 303 | I6: =+I4+I5 -> 30 | J6: =+J4+J5 -> 275 | K6: 13 | L6: =SUM(L4:L5) -> 7 | M6: =+M4+M5 -> 306 | N6: =+N4+N5 -> 31 | O6: =+O4+O5 -> 262 | P6: =SUM(P4:P5) -> 10 | Q6: =SUM(Q4:Q5) -> 6 | R6: =+R4+R5 -> 304 | S6: =+S4+S5 -> 42 | T6: =+T4+T5 -> 262 | U6: =SUM(U4:U5) -> 15 | V6: =+V4+V5 -> 6 | W6: =+W4+W5 -> 296 | X6: =+X4+X5 -> 34
C8: Solicitud Nuevos | D8: Solicitud Reconectados | E8: Activas | F8: Bolsa | G8: nuevos | H8: Total | I8: congelas | J8: Activas | K8: Bolsa | L8: Nuevos | M8: Total | N8: congelas | O8: Activas | P8: bolsa | Q8: nuevo | R8: Total | S8: congelas | T8: Activas | U8: Bolsa | V8: Nuevos | W8: Total | X8: congelas | Y8: Total cumplimiento | Z8: % de cumplimiento
B9: Aerolíneas Auto | C9: 25 | E9: 138 | F9: 5 | G9: 5 | H9: =+E9+I9 -> 166 | I9: 28 | J9: 137 | K9: 4 | L9: 1 | M9: =N9+J9 -> 164 | N9: 27 | O9: 134 | P9: 3 | Q9: 4 | R9: =+O9+S9 -> 156 | S9: 22 | T9: 133 | U9: 9 | V9: 2 | W9: =+T9+X9 -> 156 | X9: 23 | Y9: =+G9+L9+Q9+V9 -> 12 | Z9: =+Y9/(C9+D9) -> 0.48
C11: Solicitud Nuevos | D11: Solicitud Reconectados | E11: Activas | F11: Bolsa | G11: nuevos | H11: Total | I11: congelas | J11: Activas | K11: Bolsa | L11: Nuevos | M11: Total | N11: congelas | O11: Activas | P11: bolsa | Q11: nuevo | R11: Total | S11: congelas | T11: Activas | U11: Bolsa | V11: Nuevos | W11: Total | X11: congelas | Y11: Total cumplimiento | Z11: % de cumplimiento
B12: Ciudad | C12: 41 | E12: 274 | F12: 27 | G12: 10 | H12: =+E12+I12 -> 328 | I12: 54 | J12: 290 | K12: 22 | L12: 9 | M12: =+J12+N12 -> 325 | N12: 35 | O12: 268 | P12: 6 | Q12: 4 | R12: =+O12+S12 -> 323 | S12: 55 | T12: 276 | U12: 15 | V12: 3 | W12: =+T12+X12 -> 332 | X12: 56 | Y12: =+G12+L12+Q12+V12 -> 26 | Z12: =+Y12/(C12+D12) -> 0.63414634
B13: BASICS | C13: 0 | D13: 0 | E13: 5 | F13: 2 | G13: 0 | H13: =+E13+I13 -> 5 | I13: 0 | J13: 4 | K13: 2 | L13: 0 | M13: =+J13+N13 -> 5 | N13: 1 | O13: 5 | P13: 0 | Q13: 0 | R13: =S13+O13 -> 5 | S13: 0 | T13: 5 | W13: =+X13+T13 -> 5 | X13: 0 | Y13: =+G13+L13+Q13+V13 -> 0 | Z13: =+Y13/(C13+D13) -> #DIV/0!
B15: Plazas | C15: Solicitud Nuevos | D15: Solicitud Reconectados | E15: Activas | F15: Bolsa | G15: nuevos | H15: Total | I15: congelas | J15: Activas | K15: Bolsa | L15: Nuevos | M15: Total | N15: congelas | O15: Activas | P15: bolsa | Q15: nuevo | R15: Total | S15: congelas | T15: Activas | U15: Bolsa | V15: Nuevos | W15: Total | X15: congelas | Y15: Total cumplimiento | Z15: % de cumplimiento
B16: Jockey | C16: 13 | E16: 64 | G16: 0 | H16: =+E16+I16 -> 68 | I16: 4 | J16: 67 | K16: 0 | L16: 0 | M16: =+J16+N16 -> 71 | N16: 4 | O16: 68 | P16: 2 | Q16: 1 | R16: =+O16+S16 -> 68 | S16: 0 | T16: 66 | U16: 1 | V16: 0 | W16: =+T16+X16 -> 71 | X16: 5 | Y16: =+G16+L16+Q16+V16 -> 1 | Z16: =+Y16/(C16+D16) -> 0.076923077
B17: La Marina | C17: 11 | E17: 21 | F17: 1 | G17: 1 | H17: =+E17+I17 -> 26 | I17: 5 | J17: 22 | K17: 0 | L17: 0 | M17: =+J17+N17 -> 27 | N17: 5 | O17: 28 | P17: 0 | Q17: 0 | R17: =+O17+S17 -> 28 | S17: 0 | T17: 26 | U17: 0 | V17: 0 | W17: =+T17+X17 -> 27 | X17: 1 | Y17: =+G17+L17+Q17+V17 -> 1 | Z17: =+Y17/(C17+D17) -> 0.090909091
B18: Bellavista | C18: 7 | E18: 33 | G18: 0 | H18: =+E18+I18 -> 36 | I18: 3 | J18: 31 | K18: 0 | L18: 0 | M18: =+J18+N18 -> 36 | N18: 5 | O18: 33 | P18: 1 | Q18: 1 | R18: =+O18+S18 -> 34 | S18: 1 | T18: 36 | U18: 1 | V18: 0 | W18: =+T18+X18 -> 36 | X18: 0 | Y18: =+G18+L18+Q18+V18 -> 1 | Z18: =+Y18/(C18+D18) -> 0.14285714
B19: Angamos | C19: 5 | E19: 6 | G19: 0 | H19: =+E19+I19 -> 7 | I19: 1 | J19: 4 | K19: 0 | L19: 0 | M19: =+J19+N19 -> 6 | N19: 2 | O19: 4 | P19: 0 | Q19: 0 | R19: =+O19+S19 -> 4 | S19: 0 | T19: 4 | U19: 0 | V19: 0 | W19: =+T19+X19 -> 4 | X19: 0 | Y19: =+G19+L19+Q19+V19 -> 0 | Z19: =+Y19/(C19+D19) -> 0
B20: Total flota | E20: =SUM(E16:E19) -> 124 | F20: =+F16+F17+F18+F19 -> 1 | G20: =SUM(G16:G19) -> 1 | H20: =SUM(H16:H19) -> 137 | I20: =SUM(I16:I19) -> 13 | P20: =SUM(P16:P19) -> 3 | Q20: =SUM(Q16:Q19) -> 2 | U20: =SUM(U16:U19) -> 2 | V20: 0 | Y20: =SUM(Y16:Y19) -> 3

Sheet MARZO
B2: Afiliación | C2: Ope proy | E2: 45726 | J2: 45733 | O2: 45740 | T2: 45747
C3: Solicitud Nuevos | D3: Solicitud Reconectados | E3: Activas | F3: Bolsa | G3: nuevos | H3: Total | I3: congelas | J3: Activas | K3: Bolsa | L3: Nuevos | M3: Total | N3: congelas | O3: Activas | P3: Bolsa | Q3: Nuevos | R3: Total | S3: congelas | T3: Activas | U3: Bolsa | V3: Nuevos | W3: Total | X3: congelas | Y3: Total cumplimiento | Z3: % de cumplimiento
B4: Aeropuerto Auto | C4: 30 | D4: 15 | E4: 237 | F4: 16 | G4: 10 | H4: =+I4+E4 -> 271 | I4: 34 | J4: 247 | K4: 12 | L4: 7 | M4: =+N4+J4 -> 270 | N4: 23 | O4: 249 | P4: 12 | Q4: 8 | R4: =+S4+O4 -> 276 | S4: 27 | T4: 248 | U4: 15 | V4: 9 | W4: =+X4+T4 -> 278 | X4: 30 | Y4: =+G4+L4+Q4+V4 -> 34 | Z4: =+Y4/(C4+D4) -> 0.75555556
B5: Aeropuerto Van | C5: 7 | D5: 3 | E5: 17 | H5: =+E5+I5 -> 18 | I5: 1 | J5: 17 | M5: =+J5+N5 -> 18 | N5: 1 | O5: 16 | R5: =+O5+S5 -> 19 | S5: 3 | T5: 18 | W5: =+T5+X5 -> 20 | X5: 2 | Y5: =+G5+L5+Q5+V5 -> 0 | Z5: =+Y5/(C5+D5) -> 0
B6: Total Flota | D6: 55 | E6: =+E4+E5 -> 254 | H6: =+H4+H5 -> 289 | I6: =+I4+I5 -> 35 | J6: =+J4+J5 -> 264 | M6: =+M4+M5 -> 288 | N6: =+N4+N5 -> 24 | O6: =+O4+O5 -> 265 | R6: =+R4+R5 -> 295 | S6: =+S4+S5 -> 30 | T6: =+T4+T5 -> 266 | W6: =+W4+W5 -> 298 | X6: =+X4+X5 -> 32
C8: Solicitud Nuevos | D8: Solicitud Reconectados | E8: Activas | F8: Bolsa | G8: nuevos | H8: Total | I8: congelas | J8: Activas | K8: Bolsa | L8: Solicitud Nuevos | M8: Total | N8: congelas | O8: Activas | P8: bolsa | Q8: nuevo | R8: Total | S8: congelas | T8: Activas | U8: Bolsa | V8: Nuevos | W8: Total | X8: congelas | Y8: Total cumplimiento | Z8: % de cumplimiento
B9: Aerolíneas Auto | C9: 25 | E9: 122 | F9: 10 | G9: 5 | H9: =+E9+I9 -> 145 | I9: 23 | J9: 123 | K9: 9 | L9: 5 | M9: =+J9+N9 -> 151 | N9: 28 | O9: 129 | P9: 9 | Q9: 4 | R9: =+O9+S9 -> 153 | S9: 24 | T9: 138 | U9: 7 | V9: 5 | W9: =+T9+X9 -> 160 | X9: 22 | Y9: =+G9+L9+Q9+V9 -> 19 | Z9: =+Y9/(C9+D9) -> 0.76
C11: Solicitud Nuevos | D11: Solicitud Reconectados | E11: Activas | F11: Bolsa | G11: nuevos | H11: Total | I11: congelas | J11: Activas | K11: Bolsa | L11: Solicitud Nuevos | M11: Total | N11: congelas | O11: Activas | P11: bolsa | Q11: nuevo | R11: Total | S11: congelas | T11: Activas | U11: Bolsa | V11: Nuevos | W11: Total | X11: congelas | Y11: Total cumplimiento | Z11: % de cumplimiento
B12: Ciudad | C12: 50 | E12: 277 | F12: 10 | G12: 5 | H12: =+E12+I12 -> 343 | I12: 66 | J12: 293 | K12: 13 | L12: 7 | M12: =+J12+N12 -> 336 | N12: 43 | O12: 291 | P12: 12 | Q12: 7 | R12: =+O12+S12 -> 331 | S12: 40 | T12: 278 | U12: 17 | V12: 4 | W12: =+T12+X12 -> 332 | X12: 54 | Y12: =+G12+L12+Q12+V12 -> 23 | Z12: =+Y12/(C12+D12) -> 0.46
B13: BASICS | C13: 50 | E13: 5 | G13: 0 | H13: =+E13+I13 -> 7 | I13: 2 | J13: 6 | L13: 0 | M13: =+J13+N13 -> 7 | N13: 1 | O13: 5 | Q13: 0 | R13: =+O13+S13 -> 7 | S13: 2 | T13: 5 | V13: 0 | W13: =+T13+X13 -> 5 | X13: 0 | Y13: =+G13+L13+Q13+V13 -> 0 | Z13: =+Y13/(C13+D13) -> 0
B15: Plazas | C15: Solicitud Nuevos | D15: Solicitud Reconectados | E15: Activas | F15: Bolsa | G15: nuevos | H15: Total | I15: congelas | J15: Activas | K15: Bolsa | L15: Solicitud Nuevos | M15: Total | N15: congelas | O15: Activas | P15: bolsa | Q15: nuevo | R15: Total | S15: congelas | T15: Activas | U15: Bolsa | V15: Nuevos | W15: Total | X15: congelas | Y15: Total cumplimiento | Z15: % de cumplimiento
B16: Jockey | C16: 8 | D16: 4 | E16: 60 | F16: 0 | G16: 0 | H16: =+E16+I16 -> 67 | I16: 7 | J16: 60 | K16: 1 | L16: 0 | M16: =+J16+N16 -> 65 | N16: 5 | O16: 63 | P16: 1 | Q16: 0 | R16: =+O16+S16 -> 67 | S16: 4 | T16: 63 | V16: 1 | W16: =+T16+X16 -> 67 | X16: 4 | Y16: =+G16+L16+Q16+V16 -> 1 | Z16: =+Y16/(C16+D16) -> 0.083333333
B17: La Marina | C17: 5 | D17: 3 | E17: 22 | G17: 0 | H17: =+E17+I17 -> 25 | I17: 3 | J17: 22 | L17: 0 | M17: =+J17+N17 -> 25 | N17: 3 | O17: 23 | Q17: 0 | R17: =+O17+S17 -> 26 | S17: 3 | T17: 21 | V17: 1 | W17: =+T17+X17 -> 26 | X17: 5 | Y17: =+G17+L17+Q17+V17 -> 1 | Z17: =+Y17/(C17+D17) -> 0.125
B18: Bellavista | C18: 3 | D18: 1 | E18: 28 | G18: 0 | H18: =+E18+I18 -> 37 | I18: 9 | J18: 31 | L18: 0 | M18: =+J18+N18 -> 37 | N18: 6 | O18: 33 | Q18: 0 | R18: =+O18+S18 -> 36 | S18: 3 | T18: 32 | U18: 1 | V18: 0 | W18: =+T18+X18 -> 36 | X18: 4 | Y18: =+G18+L18+Q18+V18 -> 0 | Z18: =+Y18/(C18+D18) -> 0
B19: Angamos | C19: 3 | D19: 1 | E19: 6 | G19: 0 | H19: =+E19+I19 -> 7 | I19: 1 | J19: 5 | L19: 0 | M19: =+J19+N19 -> 6 | N19: 1 | O19: 5 | Q19: 0 | R19: =+O19+S19 -> 6 | S19: 1 | T19: 6 | V19: 1 | W19: =+T19+X19 -> 7 | X19: 1 | Y19: =+G19+L19+Q19+V19 -> 1 | Z19: =+Y19/(C19+D19) -> 0.25
B20: Total flota | C20: 28 | D20: =SUM(D16:D19) -> 9 | E20: =SUM(E16:E19) -> 116 | H20: =SUM(H16:H19) -> 136 | I20: =SUM(I16:I19) -> 20 | J20: =SUM(J16:J19) -> 118 | M20: =SUM(M16:M19) -> 133 | N20: =SUM(N16:N19) -> 15 | O20: =SUM(O16:O19) -> 124 | R20: =SUM(R16:R19) -> 135 | S20: =SUM(S16:S19) -> 11 | T20: =SUM(T16:T19) -> 122 | V20: 3 | W20: =SUM(W16:W19) -> 136 | X20: =SUM(X16:X19) -> 14 | Y20: =SUM(Y16:Y19) -> 3

Sheet FUNNEL DE CONVERSIÓN
B1: 1 | C1: 3 | D1: 4 | E1: 5 | G1: 6 | H1: 7
A2: Semana 14 | B2: Leads | C2: Antecedentes (BOLSA) | D2: Entrevista | E2: Proceso de capa | F2: Capacitacion Programada | G2: Capacitados (Nuevos) | H2: Activos (1er viaje) | I2: Metas de viajes (Sem) | J2: # Cantidad con meta cumplida | K2: Total cumplimiento | L2: % de cumplimiento | M2: FLOTA ACTIVA Sem 13 | N2: FLOTA ACTIVA Sem 14 | O2: DIFERENCIA
A3: Aeropuerto Auto | B3: 50 | C3: 4 | D3: 3 | E3: 3 | F3: 5 | G3: 5 | H3: 8 | K3: =ABRIL!Y4 -> 24 | L3: =ABRIL!Z4 -> 0.58536585 | M3: =ABRIL!E4 -> 254 | N3: =ABRIL!J4 -> 257 | O3: =N3-M3 -> 3
A4: Aeropuerto Van | C4: 0 | K4: =ABRIL!Y5 -> 0 | L4: =ABRIL!Z5 -> 0 | M4: =ABRIL!E5 -> 19 | N4: =ABRIL!J5 -> 18 | O4: =N4-M4 -> -1
A5: Aerolíneas Auto | C5: 2 | D5: 2 | E5: 3 | F5: 5 | G5: 5 | K5: =ABRIL!Y9 -> 12 | L5: =ABRIL!Z9 -> 0.48 | M5: =ABRIL!E9 -> 138 | N5: =ABRIL!J9 -> 137 | O5: =N5-M5 -> -1
A6: Ciudad | B6: 100 | C6: 7 | D6: 3 | E6: 14 | F6: 11 | G6: 9 | K6: =ABRIL!Y12 -> 26 | L6: =ABRIL!Z12 -> 0.63414634 | M6: =ABRIL!E12 -> 274 | N6: =ABRIL!J12 -> 290 | O6: =N6-M6 -> 16
A7: BASICS | E7: 2 | M7: =ABRIL!E13 -> 5 | N7: =ABRIL!J13 -> 4 | O7: =N7-M7 -> -1
A8: Jockey | C8: 0 | D8: 0 | E8: 0 | F8: 0 | M8: =ABRIL!E16 -> 64 | N8: =ABRIL!J16 -> 67 | O8: =N8-M8 -> 3
A9: La Marina | C9: 0 | D9: 2 | E9: 2 | F9: 2 | G9: 2 | M9: =ABRIL!E17 -> 21 | N9: =ABRIL!J17 -> 22 | O9: =N9-M9 -> 1
A10: Bellavista | C10: 0 | D10: 0 | E10: 0 | F10: 0 | M10: =ABRIL!E18 -> 33 | N10: =ABRIL!J18 -> 31 | O10: =N10-M10 -> -2
A11: Angamos | C11: 0 | D11: 0 | E11: 0 | F11: 0 | M11: =ABRIL!E19 -> 6 | N11: =ABRIL!J19 -> 4 | O11: =N11-M11 -> -2
A13: Semana 15 | B13: Leads | C13: Antecedentes (BOLSA) | D13: Entrevista | E13: Proceso de capa | F13: Capacitacion Programada | G13: Capacitados (Nuevos) | H13: Activos (1er viaje) | I13: Metas de viajes (Sem) | J13: # Cantidad con meta cumplida | K13: Total cumplimiento | L13: % de cumplimiento | M13: FLOTA ACTIVA Sem 14 | N13: FLOTA ACTIVA Sem 15 | O13: DIFERENCIA
A14: Aeropuerto Auto | M14: =N3 -> 257 | N14: =ABRIL!O4 -> 246 | O14: =N14-M14 -> -11
A15: Aeropuerto Van | M15: =N4 -> 18 | N15: =ABRIL!O5 -> 16 | O15: =N15-M15 -> -2
A16: Aerolíneas Auto | M16: =N5 -> 137 | N16: =ABRIL!O9 -> 134 | O16: =N16-M16 -> -3
